Workbook

Sheet WORKLOG AWS FCJ
A2: Day | B2: Task | C2: Describe | D2: Labels | E2: State | F2: Start date | G2: Due date | H2: Deliverable | I2: Notes
A3: 45789 | B3: Learning Knowledge about AWS | D3: 🛠️ Practice | E3: Done
A4: 45778 | E4: To do
A5: 45779 | E5: To do
A6: 45780 | E6: To do
A7: 45781 | E7: To do
A8: 45782 | E8: To do
A9: 45783 | E9: To do
A10: 45784 | E10: To do
A11: 45785 | E11: To do
A12: 45786 | E12: To do
A13: 45787 | E13: To do
A14: 45788 | E14: To do
A15: 45789 | E15: To do
... A79: 45853 | E79: To do

Sheet Daily Report
A1: Date | B1: Week # | C1: Check-in | D1: Check-out | E1: Total Hours | F1: Daily Goals | G1: Tasks Completed | H1: Challenges | I1: Solutions | J1: Tomorrow's Plan | K1: Documents | L1: Note | M1: Mentor Feedback
A2: 45789 | B2: 1 | C2: 14:00 | D2: 19:00 | E2: =IF(AND(D2<>"",C2<>""), (D2-C2)*24, "") -> 5 | F2: Xem video, nghiên cứu các kiến thức cơ bản và keyword đồng thời làm quiz trắc nghiệm "Week 1: Network foundation" | G2: - Nắm rõ khái niệm về điện toán đám mây - Các lợi ích của điện toán đám mây mang lại - Đọc tài liệu và tìm hiểu về các thuật ngữ chuyên ngành - Hoàn thành các câu hỏi trắc nghiệm cuối bài và đạt chứng nhận Week 1 | J2: Tạo tài khoản AWS và tiến hành đọc tài liệu cho bài lab thực hành để tiện cho việc làm lab sau này thuận lợi hơn. | K2: 1. Link bài lab học tập: https://000001.awsstudygroup.com/1-create-new-aws-account/ 2. Link lý thuyết: https://specialforce.awsstudygroup.com/#/course/week-1:-network-foundation | L2: Học tập và làm việc tại nhà
A3: 45790 | B3: 1 | C3: 15:00 | D3: 20:00 | E3: =IF(AND(D3<>"",C3<>""), (D3-C3)*24, "") -> 5 | F3: Tạo tài khoản AWS và đọc sơ lược các module cũng như lên lộ trình cho tài liệu thực hành | G3: - Tạo thành công tài khoản AWS. - Đăng nhập vào thao tác với các công cụ và tìm hiểu các tác vụ, tài nguyên trong trang AWS. | J3: Tiến hành tạo MFA cho tài khoản AWS | K3: Link lý thuyết: https://specialforce.awsstudygroup.com/ Link bài lab thực hành: https://cloudjourney.awsstudygroup.com/1-explore/ | L3: Học tập và làm việc tại nhà
A4: 45791 | B4: 1 | C4: 15:00 | D4: 18:30 | E4: =IF(AND(D4<>"",C4<>""), (D4-C4)*24, "") -> 3.5 | F4: 1. Lab module 1: "MFA for AWS Accounts" 2. Xem video, học các kiến thức keyword và làm quiz trắc nghiệm "Week 2: Database and storage foundation" | G4: - Tạo khoá bảo mật MFA bằng google authentication connect với AWS sử dụng điện thoại để nhập mã 6 số và đăng nhập vào tài khoản nhằm tăng tính bảo mật cao. - Hoàn thành bài quiz cuối bài học và đạt chứng nhận week 2. | J4: 1. Học lý thuyết week 3, 4. 2. Làm lab module 1: AWS IAM, AWS Budgets, Amazon VPC | K4: 1. Link bài lab học tập: https://000001.awsstudygroup.com/2-mfa-setup-for-aws-user-root/ 2. Link lý thuyết: https://specialforce.awsstudygroup.com/#/course/week-2:-database-and-storage-foundation 3. Link word lab: Module 1: MFA for AWS Account | L4: Học tập và làm việc tại nhà
A5: 45792 | B5: 1 | C5: 14:00 | D5: 21:30 | E5: =IF(AND(D5<>"",C5<>""), (D5-C5)*24, "") -> 7.5 | F5: 1. Xem video, học các kiến thức keyword, làm quiz trắc nghiệm "Week 3: Soft skills and SoW Best practices" 2. Xem video, học các kiến thức keyword, làm quiz trắc nghiệm "Week 4: Amazon EKS" 3. Làm lab module 1: "AWS IAM, AWS Budgets, Amazon VPC" | G5: 1. Hoàn thành các câu hỏi và đạt chứng nhận của Week 3 và Week 4 bao gồm đã nắm được các kiến thức: + Week 3: Học được các kỹ năng mềm trong quá trình làm việc với khách hàng: SOW for POC & Non-MAP. + Week 4: Nắm bắt được các kiến thức và khái niệm về Amazon Elastic Kubernetes Service (EKS) về: AWS Amazon EKS Overview, AWS EKS Endpoint Access, AWS EKS Pods Networking, AWS Exposing Applications, AWS Amazon EKS Storage, AWS Amazon EKS Autoscaling. 2. Cấu hình quyền truy cập với AWS IAM: tạo Admin Group, Admin User lấy tên FCJ-User với quyền truy cập AWS Management Console và gán IAM User đó vào nhóm quản trị sau đó thiết lập MFA cho User đó giống như Root User. 3. AWS Budgets - Tìm hiểu về các dịch vụ, lợi ích mà quản lý chi phí với AWS Budgets mang lại: + Hiểu và nắm rõ về 4 loại ngân sách do AWS Budgets hỗ trợ: Cost Budget, Usage Budget, RI Budget và Savings Plans Budget. + Thiết lập loại ngân sách là Usage Budget cho ngày và tháng sau đó chọn cấu hình ngưỡng cảnh báo là 80% để gửi mail cho việc là ngày hôm nay hoặc tháng này bạn đã sử dụng chi phí gần đạt ngưỡng cho phép. Việc tạo Budgets này nhằm quản lý chi phí 1 cách hiệu quả, minh bạch và rõ ràng giúp mình an tâm và sử dụng. 4. Amazon Virtual Private Cloud (VPC): thao tác đơn giản với việc tạo các mạng với Amazon VPC bao gồm: tạo VPC, tạo subnet, tạo internet gateway, tạo route table, tạo security group, tạo EC2, tạo NAT Gateway, tạo môi trường và cấu hình kết nối VPN, clean resource để tránh tăng chi phí sử dụng tài nguyên. | H5: Quên clean up tài nguyên của NAT Gateway dẫn đến việc phát sinh chi phí | I5: Sau này rút kinh nghiệm sau khi làm xong mọi thứ trong 1 phần module thì bỏ 1 phần thời gian check kỹ tất cả các dịch vụ để kịp thời clean up tài nguyên tránh phát sinh chi phí | J5: Xem video học lý thuyết week 5: "Amazon ECS and Fargate" | K5: 1. Link bài lab học tập: https://000001.awsstudygroup.com/1-create-new-aws-account/ 2. Link lý thuyết week 3: https://specialforce.awsstudygroup.com/#/course/week-3:-soft-skills-and-sow-best-practices 3. Link lý thuyết week 4: https://specialforce.awsstudygroup.com/#/course/week-4:-amazon-eks | L5: Học tập và làm việc tại nhà
A6: 45793 | B6: 1 | C6: 15:00 | D6: 18:00 | E6: =IF(AND(D6<>"",C6<>""), (D6-C6)*24, "") -> 3 | F6: Xem video, nghiên cứu các kiến thức cơ bản và keyword đồng thời làm quiz trắc nghiệm "Week 5: Amazon ECS and Fargate" | G6: Hoàn thành các câu quiz cuối bài học và đạt chứng nhận cho week 5 bao gồm hiểu và nắm các kiến thức về Elastic Container Service (ECS) và AWS Fargate gồm: AWS Intro of ECS and Fargate, AWS Amazon ECS overview, AWS ECS Service Architecture, AWS Fargate Overview, AWS Integrate ECS with the other AWS Services, AWS Good questions to ask your customers, AWS Lab for ECS and Fargate. | J6: 1. Xem video và làm quiz cho tuần 6 2. Thực hành lab module 2 phần EC2 | K6: Link lý thuyết: https://specialforce.awsstudygroup.com/#/course/week-5:-amazon-ecs-and-fargate | L6: Học tập và làm việc tại nhà
A7: 45794 | B7: 1 | C7: 13:00 | D7: 19:00 | E7: =IF(AND(D7<>"",C7<>""), (D7-C7)*24, "") -> 6 | F7: 1. Xem video, nghiên cứu các kiến thức cơ bản và keyword đồng thời làm quiz trắc nghiệm "Week 6: Observability & Cost Management" 2. Xem video module 2 trên 'AWS First Cloud Bootcamps - 2025' để hiểu rõ hơn cách anh dạy kinh nghiệm làm lab về EC2. 3. Thực hành bài lab về Amazon Elastic Compute Cloud (EC2). | G7: 1. Hoàn thành bài quiz trắc nghiệm cuối bài học và lấy chứng nhận Week 6 2. Nắm được kiến thức cơ bản về máy chủ ảo với Amazon Elastic Compute Cloud (EC2) bao gồm: - Tạo VPC Linux - Tạo VPC Windows - Tạo Security Group Linux - Tạo Security Group Windows - Tạo Windows Instance - Kết nối Windows instance - Tạo Linux instance - Kết nối Linux instance - Thay đổi cấu hình EC2 - Tạo EC2 snapshot - Tạo Custom AMI - Tạo instance từ custom AMI - Cài đặt XAMPP trên Windows instance - Cài đặt Nodejs trên Windows instance - Clean up tài nguyên | J7: Xem video học lý thuyết và làm week 7: "Migrate & Modernize with AWS" | K7: 1. Link bài lab học tập: https://000004.awsstudygroup.com/1-introduce/ 2. Link lý thuyết: https://specialforce.awsstudygroup.com/#/course/week-6:-observability-&-cost-management | L7: Học tập và làm việc tại nhà
A8: 45795 | B8: 1 | C8: 16:30 | D8: 19:30 | E8: =IF(AND(D8<>"",C8<>""), (D8-C8)*24, "") -> 3 | F8: 1. Xem video, nghiên cứu các kiến thức cơ bản và keyword đồng thời làm quiz trắc nghiệm "Week 7: Migrate & Modernize with AWS" | G8: 1.Hoàn thành bài học từ các video lý thuyết và lấy chứng nhận lý thuyết week 7 2.Nắm được kiến thức và hạ tầng lên aws, kỹ năng trong quá trình Migrate & Modernize của ứng dụng bao gồm: - Migration customer journey - Migration Evaluator - Application Discovery Service (ADS) & Migration Hub - 7R migration pattern analysis - Migration Readiness Assessment and Migration Portfolio Assessment - AWS Application Migration Service | J8: - Lên văn phòng học tập, học hỏi và giao lưu với các bạn, các anh tại tầng 26 văn phòng công ty AWS ở toà nhà Bitexco - Xem video học lý thuyết và làm quiz cho week 8: "Managing and Governing multi-account AWS environments" | K8: Link lý thuyết: https://specialforce.awsstudygroup.com/#/course/week-7:-migrate-&-modernize-with-aws | L8: Học tập và làm việc tại nhà
A9: 45796 | B9: 2 | C9: 9:00 | D9: 17:00 | E9: =IF(AND(D9<>"",C9<>""), (D9-C9)*24, "") -> 8 | F9: 1. Lên văn phòng sớm hơn dự kiến là 8:30 để học tập và giao lưu tại tầng 26 2. Xem video, nghiên cứu lý thuyết và làm quiz "Week 8: Managing and Governing multi-account AWS environments" | G9: 1. Hoàn thành việc lên văn phòng checkin đúng giờ vào lúc 9:00 và điểm danh cuối buổi vào lúc 17:00 tại tầng 26. 2. Hoàn thành việc xem video lý thuyết và làm quiz cuối bài để có chứng nhận hoàn thành week 8 bao gồm các kiến thức đã nắm và hiểu được: - Managing and Governing multi-account AWS environments - Using AWS Control Tower to govern multi-account AWS environments at scale - AWS Landing Zone best practices | J9: 1. Làm lab thực hành module 2 phần IAM Roles for EC2. 2. Xem video và làm quiz cho Week 9: Migration factory | K9: Link lý thuyết: https://specialforce.awsstudygroup.com/#/course/week-8:-managing-and-governing-multi-account-aws-environments. | L9: Học tập và làm việc tại tầng 26
A10: 45797 | B10: 2 | C10: 14:00 | D10: 19:00 | E10: =IF(AND(D10<>"",C10<>""), (D10-C10)*24, "") -> 5 | F10: 1. Làm lab thực hành module 2 trong phần "Cấp quyền với IAM Roles For EC2" 2. Xem video, nghiên cứu, học và hiểu thêm các keyword mới và làm quiz về "Week 9: Migration factory" | G10: 1. Hoàn thành bài lab "Cấp quyền ứng dụng với IAM Roles for EC2" bao gồm các phần: - Tạo IAM user và access key - Sử dụng access key - Tạo và sử dụng IAM role - Clean up tài nguyên 2. Hoàn thành xem các video và làm quiz cuối bài để lấy được chứng nhận week 9 bao gồm các khái niệm và quy trình vận hành Migration factory để giúp tăng tốc và di chuyển ứng dụng nhanh chóng lên AWS gồm các kiến thức: - AWS Application Migration Service (AWS MGN) - Migration Factory - Part 2- Disaster Recovery on AWS - Why Use Cloud-Based Disaster Recovery - Part 3- AWS Modernization With App2Container | J10: Xem video lý thuyết và làm quiz cho Week 10: Lambda and API Gateway | K10: Link lý thuyết: https://specialforce.awsstudygroup.com/#/course/week-9:-migration-factory Link thực hành: https://000048.awsstudygroup.com/2-accesskey/ | L10: Học và làm việc tại nhà
A11: 45798 | B11: 2 | C11: 15:00 | D11: 18:30 | E11: =IF(AND(D11<>"",C11<>""), (D11-C11)*24, "") -> 3.5 | F11: Xem video lý thuyết, nghiên cứu và học các khái niệm keyword mới rồi làm quiz cuối bài cho "Week 10: Lambda and API Gateway" | G11: - Hoàn thành việc xem các video lý thuyết và làm quiz cuối bài để lấy chứng nhận week 10 bao gồm các kiến thức nắm được các khái niệm và dịch vụ trong kiến trúc Serverless trên AWS: + Introduce Serverless + How Lambda Work + Best Practise with Lambda + API Gateway + SAM – Serverless Application Model | K11: Link lý thuyết: https://specialforce.awsstudygroup.com/#/course/week-10:-lambda-and-api-gateway | L11: Học và làm việc tại nhà
A12: 45799 | B12: 2 | E12: =IF(AND(D12<>"",C12<>""), (D12-C12)*24, "") | F12: Đi làm nhà hàng | L12: Làm phục vụ tại nhà hàng
A13: 45800 | B13: 2 | C13: 9:00 | D13: 16:00 | E13: =IF(AND(D13<>"",C13<>""), (D13-C13)*24, "") -> 7 | F13: - Tham dự sự kiện "AWS GenAI Builders Club" tại tầng 26 | G13: - Học hỏi được nhiều kiến thức, kinh nghiệm từ các anh trong công ty AWS chia sẻ rất hữu ích chính là GenAI - mô hình áp dụng trí tuệ nhân tạo đã và đang thực hiện trong tương lai rất mạnh mẽ. Đặc biệt là có cơ hội được gặp mặt giám đốc toàn cầu - một người rất thành công và được chia sẻ kinh nghiệm thực tiễn và lời khuyên rất hay từ anh. | L13: Lên văn phòng tham dự sự kiện GenAI tại tầng 26
A14: 45801 | B14: 2 | E14: =IF(AND(D14<>"",C14<>""), (D14-C14)*24, "") | F14: Đi làm nhà hàng | L14: Làm phục vụ tại nhà hàng
A15: 45802 | B15: 2 | E15: =IF(AND(D15<>"",C15<>""), (D15-C15)*24, "") | F15: Đi làm nhà hàng | J15: Thực hành bài lab AWS Cloud9 | L15: Làm phục vụ tại nhà hàng
A16: 45803 | B16: 3 | C16: 13:00 | D16: 17:00 | E16: =IF(AND(D16<>"",C16<>""), (D16-C16)*24, "") -> 4 | F16: Thực hành bài lab module 2 phần "Phát triển ứng dụng lên đám mây với AWS Cloud9" | G16: * Hoàn thành bài lab module 2 với AWS Cloud9: - Sử dụng command line - Làm việc với file text - Sử dụng AWS CLI | J16: Xem video lý thuyết và làm lab cho Week 11: Messaging services | K16: Link tài liệu thực hành: https://000049.awsstudygroup.com/1-createcloud9/ | L16: Học tập và làm việc tại nhà
A17: 45804 | B17: 3 | C17: 16:00 | D17: 20:00 | E17: =IF(AND(D17<>"",C17<>""), (D17-C17)*24, "") -> 4 | F17: Xem video lý thuyết, nghiên cứu và học các khái niệm keyword mới rồi làm quiz cuối bài cho "Week 11: Messaging services" | G17: * Hoàn thành xem video lý thuyết và hoàn thành bài quiz cuối bài để lấy chứng nhận week 11 đồng thời nắm được các khái niệm và các dịch vụ trong hệ thống nhắn tin (Messing Services) trên AWS bao gồm: - Introduce Messaging and EDA - Amazon Simple Store (SQS) - Amazon Simple Notification (SNS) - Amazon EventBridge & Schema | J17: Làm lab module 2 phần AWS S3 | K17: Link lý thuyết: https://specialforce.awsstudygroup.com/#/course/week-11:-messaging-services | L17: Học tập và làm việc tại nhà
A18: 45805 | B18: 3 | C18: 14:00 | D18: 19:00 | E18: =IF(AND(D18<>"",C18<>""), (D18-C18)*24, "") -> 5 | F18: Làm lab module 2 trong phần "Hosting Website tĩnh với Amazon S3" | G18: * Hoàn thành bài lab module 2 với Amazon S3 bao gồm các kiến thức đã làm và nắm được: - Tạo S3 bucket - Bật tính năng static website - Cấu hình Block Public Access và Public Object - Kiểm Tra Website - Tăng tốc Static Website với Cloudfront - Di chuyển Object - Sao chép S3 Object sang region khác - Dọn dẹp tài nguyên | J18: 1. Lên văn phòng học hỏi, học tập và giao lưu tại văn phòng tầng 26. 2. Xem video lý thuyết, làm quiz cuối bài cho "Week 12: Building Data platfrom on AWS (part 1)". 3. Làm lab thực hành phần Amazon RDS | K18: 1. Link thực hành: https://000057.awsstudygroup.com/2-prerequiste/2.1-creates3bucket/ | L18: Học tập và làm việc tại nhà
A19: 45806 | B19: 3 | C19: 9:00 | D19: 17:00 | E19: =IF(AND(D19<>"",C19<>""), (D19-C19)*24, "") -> 8 | F19: - Lên văn phòng học tập và giao lưu tại tầng 26 - Xem video, học các khái niệm, keyword mới và làm quiz cho "Week 12: Building Data platfrom on AWS (part 1)" - Làm lab module 2 phần "Tạo một cơ sở dữ liệu với Amazon Relational Database Service (RDS)" | G19: 1. Hoàn thành checkin đúng giờ vào lúc 9:00 và điểm danh cuối buổi lúc 17:00. 2. Hoàn thành xem video, làm quiz cuối buổi để lấy chứng chỉ và nắm được các khái niệm và dịch vụ trong việc xây dựng nền tảng dữ liệu data platform trên AWS gồm: - Data Lake on AWS - Ingestion - Data Transformation 3. Hoàn thành bài lab module 2 với Amazon RDS bao gồm các kiến thức đã làm và nắm được: - Tạo VPC - Tạo EC2 Security Group - Tạo RDS Security Group - Tạo DB Subnet Group - Tạo EC2 instance - Tạo RDS database instance - Triển khai ứng dụng sử dụng RDS - Clean up tài nguyên tránh phát sinh phí | J19: Xem video lý thuyết, làm quiz cuối bài "Week 13: Building Data platfrom on AWS (part 2)" | K19: 1. Link lý thuyết: https://specialforce.awsstudygroup.com/#/course/week-12:-building-data-platfrom-on-aws-(part-1) 2. Link thực hành: https://000005.awsstudygroup.com/2-prerequiste/3-create-db-sg/ | L19: Học tập và làm việc tại văn phòng tầng 26
A20: 45807 | B20: 3 | C20: 13:00 | D20: 16:30 | E20: =IF(AND(D20<>"",C20<>""), (D20-C20)*24, "") -> 3.5 | F20: - Xem video, học các khái niệm, keyword mới và làm quiz cho "Week 13: Building Data platfrom on AWS (part 2)" | G20: * Hoàn thành xem video, làm quiz cuối buổi để lấy chứng chỉ và nắm được các khái niệm xây dựng nền tảng dữ liệu hiện đại trên AWS gồm: - Module 4 – Data governance - Module 5 – Data Warehouse - Module 6 – Orchestration | J20: Off đi làm nhà hàng | K20: Link lý thuyết: https://specialforce.awsstudygroup.com/#/course/week-13:-building-data-platfrom-on-aws-(part-2) | L20: Học tập và làm việc tại nhà
A21: 45808 | B21: 3 | E21: =IF(AND(D21<>"",C21<>""), (D21-C21)*24, "") | F21: - Đi làm nhà hàng | J21: Off đi làm nhà hàng | L21: Đi làm nhà hàng phục vụ tại nhà hàng
A22: 45809 | B22: 3 | E22: =IF(AND(D22<>"",C22<>""), (D22-C22)*24, "") | F22: - Đi làm nhà hàng | J22: Xem video lý thuyết và làm quiz cho "Week 14: Introduction to Machine Learning" | L22: Đi làm phục vụ tại nhà hàng
A23: 45810 | B23: 4 | C23: 14:00 | D23: 17:30 | E23: =IF(AND(D23<>"",C23<>""), (D23-C23)*24, "") -> 3.5 | F23: - Xem video, học các khái niệm, keyword mới và làm quiz cho "Week 14: Introduction to Machine Learning" | G23: * Hoàn thành xem video, làm quiz cuối buổi để lấy chứng chỉ và nắm được các kiến thức nền tảng đã tìm hiểu trước đó cụ thể là về lĩnh vực AI - Machine Learning (ML) trong AWS bao gồm: - AWS AI_ML on AWS Introduction - AWS Amazon Rekognition Introduction & Identity Verification usecase Demo - AWS Generative AI on AWS | J23: Làm lab module 3 phần Amazon Lightsail | K23: Link lý thuyết: https://specialforce.awsstudygroup.com/#/course/week-14:-introduction-to-machine-learning | L23: Học tập và làm việc tại nhà
A24: 45811 | B24: 4 | C24: 13:00 | D24: 20:00 | E24: =IF(AND(D24<>"",C24<>""), (D24-C24)*24, "") -> 7 | F24: - Làm lab module 3 phần: "Điện toán đám mây với Amazon Lightsail" | G24: * Hoàn thành bài lab module 3 với Amazon Lightsail với các kiến thức đã làm và nắm được bao gồm: - Triển khai Wordpress Instance - Cấu hình ubuntu, Networking, WordPress - Triển khai Wordpress Instance - Triển khai Prestashop E-Commerce Instance - Bảo mật ứng dụng - Tạo snapshot - Dịch chuyển sang instance lớn hơn - Tạo cảnh báo - Clean up tài nguyên tránh phát sinh chi phí | J24: Xem video và làm quiz cho "Week 15: Gen AI training for partners" | K24: Link thực hành: https://000045.awsstudygroup.com/1-database/ | L24: Học tập và làm việc tại nhà
A25: 45812 | B25: 4 | C25: 13:30 | D25: 17:00 | E25: =IF(AND(D25<>"",C25<>""), (D25-C25)*24, "") -> 3.5 | F25: - Xem video, học các khái niệm, keyword mới và làm quiz cho "Week 15: Gen AI training for partners" | G25: * Hoàn thành xem video, làm quiz cuối bài để lấy chứng chỉ và nắm được các kiến thức nền tảng đã tìm hiểu và tham gia sự kiện GenAI trước đó cụ thể là về Generative AI gồm các kiến thức: - AWS What is Generative AI - AWS A deeper look at some of these use cases - AWS Prototyping Sharing - AWS Demo GenAI in FSI - AWS RAG - Retrieval Augmented Generation+Agent - AWS Top concerns & solutions | K25: Link lý thuyết: https://specialforce.awsstudygroup.com/#/course/week-15:-gen-ai-training-for-partners | L25: Học tập và làm việc tại nhà
A26: 45813 | B26: 4 | E26: =IF(AND(D26<>"",C26<>""), (D26-C26)*24, "") | F26: Bệnh sốt | J26: Xem video và làm quiz cho "Week 16: Threat detection and incident response using cloud native services" | L26: Học tập và làm việc tại nhà
A27: 45814 | B27: 4 | C27: 9:00 | D27: 17:00 | E27: =IF(AND(D27<>"",C27<>""), (D27-C27)*24, "") -> 8 | F27: 1. Lên văn phòng công ty học tập và làm việc tại tầng 26 2. Xem video và làm quiz cho phần "Week 16: Threat detection and incident response using cloud native services" | G27: 1. Hoàn thành lên văn phòng checkin đúng giờ vào lúc 9:00 và điểm danh cuối buổi lúc 17:00. 2. Hoàn thành xem video lý thuyết học thêm kiến thức và keyword mới và làm quiz cuối bài để lấy chứng nhận đồng thời nắm kiến thức về việc phát hiện các mối đe doạ và phản ứng các sự cố về môi trường trên đám mây dịch vụ AWS bao gồm: - The incident response lifecycle - Preparation - Detection - Collection Containment Analysis - Remediation Recovery Post-incident activity | K27: Link lý thuyết: https://specialforce.awsstudygroup.com/#/course/week-16:-threat-detection-and-incident-response-using-cloud-native-services | L27: Học tập và làm việc tại văn phòng tầng 26
A28: 45815 | B28: 4 | E28: =IF(AND(D28<>"",C28<>""), (D28-C28)*24, "") | F28: Đi làm nhà hàng | L28: Đi làm phục vụ tại nhà hàng
A29: 45816 | B29: 4 | E29: =IF(AND(D29<>"",C29<>""), (D29-C29)*24, "") | F29: Đi làm nhà hàng | L29: Đi làm phục vụ tại nhà hàng
A30: 45817 | B30: 5 | E30: =IF(AND(D30<>"",C30<>""), (D30-C30)*24, "") | F30: Bệnh sốt | L30: Bệnh sốt
A31: 45818 | B31: 5 | E31: =IF(AND(D31<>"",C31<>""), (D31-C31)*24, "") | F31: Có việc phải về quê không thể học tập và làm việc | L31: Có việc gia đình phải về quê
A32: 45819 | B32: 5 | E32: =IF(AND(D32<>"",C32<>""), (D32-C32)*24, "") | F32: Có việc phải về quê không thể học tập và làm việc | L32: Có việc gia đình phải về quê
A33: 45820 | B33: 5 | E33: =IF(AND(D33<>"",C33<>""), (D33-C33)*24, "") | F33: Có việc phải về quê không thể học tập và làm việc | L33: Có việc gia đình phải về quê
A34: 45821 | B34: 5 | C34: 13:00 | D34: 19:00 | E34: =IF(AND(D34<>"",C34<>""), (D34-C34)*24, "") -> 6 | F34: Làm lab module 3 trong phần "Giám sát hệ thống với Amazon CloudWatch" | G34: * Hoàn thành các phần bài lab trong module 3 với Amazon CloudWatch bao gồm các kiến thức về: - Thiết lập hạ tầng mạng - Khởi tạo EC2 Instance, Database Instance với Amazon RDS - Cài đặt dữ liệu cho Database - Triển khai máy chủ web - Tạo Launch Template, Load Balancer, Target Group, Auto Scaling Group - Kiểm thử giải pháp manual scaling, dynamic scaling, scheduled scaling, predictive scaling - Clean up tài nguyên để tránh phát sinh chi phí | K34: Link tài liệu thực hành: https://000008.awsstudygroup.com/3-cloud-watch-metric/ | L34: Học tập và làm việc tại nhà
A35: 45822 | B35: 5 | C35: 9:00 | D35: 16:30 | E35: =IF(AND(D35<>"",C35<>""), (D35-C35)*24, "") -> 7.5 | F35: - Lên văn phòng tham dự sự kiện "AWS FIRST CLOUD SECURITY JOURNEY" tại tầng 26 văn phòng AWS | G35: * Được chia sẻ kiến thức rất bổ ích từ anh Taki Đặng đã có hơn 20 năm kinh nghiệm trong lĩnh vực bảo mật. Đặc biệt là những chia sẻ từ team FCJ là các bạn bằng tuổi mình nhưng đã có kinh nghiệm và cách thuyết trình rất tốt điều đó khiến mình rất khâm phục và thậm chí có bạn nhỏ hơn mình 2 tuổi nhưng đã rất tự tin thuyết trình trước mọi người hơn tuổi mình thì điều đó thật đáng ngưỡng mộ! | L35: Tham gia sự kiện AWS First Cloud Security Journey tại tầng 26
A36: 45823 | B36: 5 | E36: =IF(AND(D36<>"",C36<>""), (D36-C36)*24, "") | F36: - Đi làm nhà hàng | L36: Đi làm phục vụ tại nhà hàng
A37: 45824 | B37: 6 | C37: 14:30 | D37: 17:00 | E37: =IF(AND(D37<>"",C37<>""), (D37-C37)*24, "") -> 2.5 | F37: Làm bài lab module 3: "Làm việc với database Amazon DynamoDB" | G37: * Hoàn thành việc làm tất cả các phần trong bài lab module 3 nắm được các kiến thức khi làm việc với database trong dịch vụ của AWS là DynamoDB rất tiện ích so với các công cụ database khác như MySQL, PHPMyAdmin, SQL Server... bao gồm các phần đã thao tác: - Sử dụng AWS Management Console, AWS CloudShell - Cấu hình AWS CLI - Phát triển web với Python và DynamoDB - Clean up tài nguyên để tránh phát sinh chi phí | J37: Làm bài lab module 4: "Quản lý DNS với Amazon Route 53" | K37: Link tài liệu thực hành: https://000006.awsstudygroup.com/1-introduction/ | L37: Học tập và làm việc tại nhà
A38: 45825 | B38: 6 | C38: 13:00 | D38: 20:00 | E38: =IF(AND(D38<>"",C38<>""), (D38-C38)*24, "") -> 7 | F38: Làm bài lab module 4: "Quản lý DNS lai với Amazon Route 53" | G38: * Hoàn thành việc làm lab tất cả các phần trong bài module 4 bao gồm các kiến thức đã thao tác: - Tạo Key Pair - Khởi tạo CloudFormation Template - Cấu hình Security Group - Kết nối đến RDGW - Triển khai Microsoft AD - Tạo Route 53 Outbound Endpoint, Route 53 Resolver Rules, Route 53 Inbound Endpoints - Clean up tài nguyên để tránh phát sinh chi phí | J38: Làm lab bài module 4: "AWS CLI làm việc trên Amazon EC2" | K38: Link tài liệu thực hành: https://000010.awsstudygroup.com/2-prerequiste/2.1-createkeypair/ | L38: Học tập và làm việc tại nhà
A39: 45826 | B39: 6 | C39: 13:00 | D39: 19:30 | E39: =IF(AND(D39<>"",C39<>""), (D39-C39)*24, "") -> 6.5 | F39: Làm bài lab module 4:"Sử dụng AWS CLI trên Amazon EC2" | G39: * Hoàn thành việc làm lab trong bài module 4: AWS CLI làm việc với Amazon EC2 với các thao tác: - Cài đặt AWS CLI và kiểm tra tài nguyên qua CLI - AWS CLI với Amazon S3, Amazon SNS, IAM, VPC - Tạo EC2 sử dụng AWS CLI - Clean up tài nguyên để tránh phát sinh chi phí | J39: 1. Lên văn phòng học hỏi, học tập và làm việc tại văn phòng tầng 26 2. Thực hành bài lab module 4: "Bộ nhớ đệm Amazon ElastiCache" | K39: Link tài liệu thực hành: https://000011.awsstudygroup.com/3-installcli/ | L39: Học tập và làm việc tại nhà
A40: 45827 | B40: 6 | C40: 9:00 | D40: 17:00 | E40: =IF(AND(D40<>"",C40<>""), (D40-C40)*24, "") -> 8 | F40: - Lên văn phòng công ty học tập và làm việc tại tầng 46 - Làm lab module 4: "Bộ nhớ đệm Amazon ElastiCache" | G40: 1. Hoàn thành việc checkin đúng giờ vào lúc 9:00 và điểm danh cuối buổi vào lúc 17:00 2. Hoàn thành làm các phần trong bài lab với Amazon ElastiCache với các thao tác: - Tạo AWS Access Key - Cài đặt AWS CLI và cấu hình AWS CLI - Tạo subnet group - Cấp quyền truy cập vào cluster - Kết nối với node của cluster - Xóa cluster - Tạo Elasticache cluster - Kết nối với Elasticache - Clean up tài nguyên để tránh mất chi phí | K40: Link tài liệu thực hành: https://000011.awsstudygroup.com/2-prerequiste/ | L40: Học tập và làm việc tại văn phòng tầng 26
...

Sheet Weekly Summary Report
A1: Week # | B1: Day | C1: Tổng số giờ làm việc | D1: Thành tựu chính | E1: Dịch vụ AWS đã học | F1: Kỹ năng đạt được | G1: Mục tiêu tuần tới | H1: Phản hồi của mentor
A2: 1 | B2: 15/04/2025 - 20/04/2025 | C2: =SUMIFS('Daily Report'!E:E,'Daily Report'!B:B,'Weekly Summary Report'!$A$2:$A$15) -> 33 | D2: - Hoàn thành tất cả các week từ 1 - 7 - Tạo thành công tài khoản AWS và sử dụng các dịch vụ freetier - Hoàn thành các bài lab module 1 chi tiết và hiểu rõ vấn đề - Đọc tài liệu Well - Architeched Framework | E2: - Tạo khoá bảo mật MFA - Tạo tài khoản và thao tác với IAM: User Group, Roles, Policy | F2: - Thao tác phân quyền cho từng IAM User theo group, role và policy - Đọc tài liệu bằng tiếng anh nhanh và dễ hiểu với Well - Architeched Framework.
A3: 2 | B3: 21/04/2025 - 27/04/2025 | C3: =SUMIFS('Daily Report'!E:E,'Daily Report'!B:B,'Weekly Summary Report'!$A$2:$A$15) -> 23.5
A4: 3 | B4: 28/04/2025 - 04/05/2025 | C4: =SUMIFS('Daily Report'!E:E,'Daily Report'!B:B,'Weekly Summary Report'!$A$2:$A$13) -> 24.5
A5: 4 | B5: 05/05/2025 - 11/05/2025 | C5: =SUMIFS('Daily Report'!E:E,'Daily Report'!B:B,'Weekly Summary Report'!$A$2:$A$13) -> 22
A6: 5 | B6: 12/05/2025 - 18/05/2025 | C6: 28
A7: 6 | B7: 19/05/2025 - 25/05/2025 | C7: =SUMIFS('Daily Report'!E:E,'Daily Report'!B:B,'Weekly Summary Report'!$A$2:$A$13) -> 30
A8: 7 | B8: 26/05/2025 - 01/06/2025 | C8: 31
A9: 8 | B9: 02/06/2025 - 08/06/2025 | C9: 25
A10: 9 | B10: 09/06/2025 - 15/06/2025 | C10: 35
A11: 10 | B11: 16/06/2025 - 22/06/2025 | C11: 43
A12: 11 | B12: 23/06/2025 - 29/06/2025 | C12: 45
A13: 12 | B13: 30/06/2025 - 10/07/2025 | C13: 53

Sheet WORKLOG WORKSHOP
A2: Day | B2: Task | C2: Describe | D2: Labels | E2: State | F2: Start date | G2: Due date | H2: Deliverable

Sheet SELF-ASSESSMENT
A2: Thông tin cơ bản
A3: Họ và tên | B3: Trần Thiên Đức
A4: MSSV | B4: 2180609568
A5: Số điện thoại | B5: 0845057921
A6: Email | B6: ductran06629@gmail.com
A7: Vị trí thực tập | B7: FCJ Trainee
A8: Người hướng dẫn | B8: Văn Hoàng Kha
A9: Định hướng phát triển | B9: Trở thành Cloud Computer
A10: Nhiệm vụ phân công
A11: Link Notion
A12: Link Github | B12: https://github.com/DucTranThien
A13: Thời gian thực tập
A14: Ngày bắt đầu | B14: 45789
A15: Ngày kết thúc dự kiến | B15: 45881
A16: Tổng số tuần | B16: 14
A17: Số giờ yêu cầu mỗi tuần | B17: 30
A18: Bảng theo dõi tiến độ
A19: Tổng số giờ đã làm việc | B19: =SUM('Daily Report'!E:E) -> 208.5
A20: Tỷ lệ hoàn thành
A21: Số ngày đã thực tập | B21: 6
A22: Nội dung tự đánh giá
A23: 1. Thái độ, chấp hành kỷ luật
A24: 2. Kỹ năng mềm
A25: 3. Kiến thức chuyên môn
A26: Thành tích thực tập
A36: Công việc khác
